<?xml version="1.0" encoding="UTF-8"?>
<!-- Generated by org.testng.reporters.JUnitReportReporter -->
<testsuite hostname="akhilessharma01" failures="0" tests="3" name="TestCases.Customer_Register_Cognito" time="37.978" errors="1" timestamp="19 Apr 2021 05:38:37 GMT" skipped="2">
  <testcase classname="TestCases.Customer_Register_Cognito" name="customer_register_cognito" time="0.071">
    <skipped/>
  </testcase> <!-- customer_register_cognito -->
  <testcase classname="TestCases.Customer_Register_Cognito" name="customer_register_cognito" time="37.819">
    <skipped/>
  </testcase> <!-- customer_register_cognito -->
  <testcase classname="TestCases.Customer_Register_Cognito" name="customer_register_cognito" time="0.088">
    <error message="wrong number of arguments" type="java.lang.IllegalArgumentException">
      <![CDATA[java.lang.IllegalArgumentException: wrong number of arguments
	at java.base/jdk.internal.reflect.NativeMethodAccessorImpl.invoke0(Native Method)
	at java.base/jdk.internal.reflect.NativeMethodAccessorImpl.invoke(NativeMethodAccessorImpl.java:64)
	at java.base/jdk.internal.reflect.DelegatingMethodAccessorImpl.invoke(DelegatingMethodAccessorImpl.java:43)
	at java.base/java.lang.reflect.Method.invoke(Method.java:564)
	at org.testng.internal.MethodInvocationHelper.invokeMethod(MethodInvocationHelper.java:108)
	at org.testng.internal.Invoker.invokeMethod(Invoker.java:661)
	at org.testng.internal.Invoker.retryFailed(Invoker.java:1014)
	at org.testng.internal.Invoker.invokeTestMethods(Invoker.java:1215)
	at org.testng.internal.TestMethodWorker.invokeTestMethods(TestMethodWorker.java:126)
	at org.testng.internal.TestMethodWorker.run(TestMethodWorker.java:109)
	at org.testng.TestRunner.privateRun(TestRunner.java:744)
	at org.testng.TestRunner.run(TestRunner.java:602)
	at org.testng.SuiteRunner.runTest(SuiteRunner.java:380)
	at org.testng.SuiteRunner.runSequentially(SuiteRunner.java:375)
	at org.testng.SuiteRunner.privateRun(SuiteRunner.java:340)
	at org.testng.SuiteRunner.run(SuiteRunner.java:289)
	at org.testng.SuiteRunnerWorker.runSuite(SuiteRunnerWorker.java:52)
	at org.testng.SuiteRunnerWorker.run(SuiteRunnerWorker.java:86)
	at org.testng.TestNG.runSuitesSequentially(TestNG.java:1301)
	at org.testng.TestNG.runSuitesLocally(TestNG.java:1226)
	at org.testng.TestNG.runSuites(TestNG.java:1144)
	at org.testng.TestNG.run(TestNG.java:1115)
	at org.testng.remote.AbstractRemoteTestNG.run(AbstractRemoteTestNG.java:115)
	at org.testng.remote.RemoteTestNG.initAndRun(RemoteTestNG.java:251)
	at org.testng.remote.RemoteTestNG.main(RemoteTestNG.java:77)
]]>
    </error>
  </testcase> <!-- customer_register_cognito -->
</testsuite> <!-- TestCases.Customer_Register_Cognito -->
